sample_data/BTCUSDT/2020-11-01T09-00-00_trades.json
[{"e": "aggTrade", "E": 1604221200091, "s": "BTCUSDT", "a": 408202367, "p": "13748.62000000", "q": "0.00836900", "f": 448745700, "l": 448745700, "T": 1604221200090, "m": false, "M": true}, {"e": "aggTrade", "E": 1604221200092, "s": "BTCUSDT", "a": 408202368, "p": "13748.74000000", "q": "0.00900000", "f": 448745701, "l": 448745701, "T": 1604221200091, "m": false, "M": true}, {"e": "aggTrade", "E": 1604221200092, "s": "BTCUSDT", "a": 408202369, "p": "13748.85000000", "q": "0.00425500", "f": 448745702, "l": 448745703, "T": 1604221200091, "m": false, "M": true}, {"e": "aggTrade", "E": 1604221200092, "s": "BTCUSDT", "a": 408202370, "p": "13748.91000000", "q": "0.01134000", "f": 448745704, "l": 448745704, "T": 1604221200091, "m": false, "M": true}, {"e": "aggTrade", "E": 1604221200309, "s": "BTCUSDT", "a": 408202371, "p": "13748.92000000", "q": "0.00800500", "f": 448745705, "l": 448745705, "T": 1604221200308, "m": false, "M": true}, {"e": "aggTrade", "E": 1604221200340, "s": "BTCUSDT", "a": 408202372, "p": "13748.92000000", "q": "0.00999500", "f": 448745706, "l": 448745707, "T": 1604221200339, "m": false, "M": true}, {"e": "aggTrade", "E": 1604221200569, "s": "BTCUSDT", "a": 408202373, "p": "13748.99000000", "q": "0.00206500", "f": 448745708, "l": 448745708, "T": 1604221200568, "m": false, "M": true}, {"e": "aggTrade", "E": 1604221200780, "s": "BTCUSDT", "a": 408202374, "p": "13748.99000000", "q": "0.01197000", "f": 448745709, "l": 448745709, "T": 1604221200779, "m": false, "M": true}, {"e": "aggTrade", "E": 1604221201107, "s": "BTCUSDT", "a": 408202375, "p": "13748.99000000", "q": "0.00809800", "f": 448745710, "l": 448745710, "T": 1604221201106, "m": false, "M": true}, {"e": "aggTrade", "E": 1604221201238, "s": "BTCUSDT", "a": 408202376, "p": "13748.99000000", "q": "0.00083900", "f": 448745711, "l": 448745711, "T": 1604221201237, "m": false, "M": true}, {"e": "aggTrade", "E": 1604221201242, "s": "BTCUSDT", "a": 408202377, "p": "13748.99000000", "q": "0.00312700", "f": 448745712, "l": 448745712, "T": 1604221201241, "m": false, "M": true}, {"e": "aggTrade", "E": 1604221201742, "s": "BTCUSDT", "a": 408202378, "p": "13748.98000000", "q": "0.00867000", "f": 448745713, "l": 448745713, "T": 1604221201741, "m": true, "M": true}, {"e": "aggTrade", "E": 1604221201830, "s": "BTCUSDT", "a": 408202379, "p": "13748.99000000", "q": "0.00226100", "f": 448745714, "l": 448745714, "T": 1604221201829, "m": false, "M": true}, {"e": "aggTrade", "E": 1604221201942, "s": "BTCUSDT", "a": 408202380, "p": "13748.99000000", "q": "0.00650000", "f": 448745715, "l": 448745715, "T": 1604221201941, "m": false, "M": true}, {"e": "aggTrade", "E": 1604221202280, "s": "BTCUSDT", "a": 408202381, "p": "13748.99000000", "q": "0.00200000", "f": 448745716, "l": 448745716, "T": 1604221202279, "m": false, "M": true}, {"e": "aggTrade", "E": 1604221202364, "s": "BTCUSDT", "a": 408202382, "p": "13748.99000000", "q": "0.22642900", "f": 448745717, "l": 448745717, "T": 1604221202363, "m": false, "M": true}, {"e": "aggTrade", "E": 1604221202389, "s": "BTCUSDT", "a": 408202383, "p": "13748.99000000", "q": "0.00229000", "f": 448745718, "l": 448745718, "T": 1604221202389, "m": false, "M": true}, {"e": "aggTrade", "E": 1604221202549, "s": "BTCUSDT", "a": 408202384, "p": "13748.99000000", "q": "0.05692800", "f": 448745719, "l": 448745719, "T": 1604221202548, "m": false, "M": true}, {"e": "aggTrade", "E": 1604221203045, "s": "BTCUSDT", "a": 408202385, "p": "13748.99000000", "q": "0.75000000", "f": 448745720, "l": 448745720, "T": 1604221203044, "m": false, "M": true}, {"e": "aggTrade", "E": 1604221203089, "s": "BTCUSDT", "a": 408202386, "p": "13748.99000000", "q": "0.14091000", "f": 448745721, "l": 448745721, "T": 1604221203087, "m": false, "M": true}, {"e": "aggTrade", "E": 1604221203266, "s": "BTCUSDT", "a": 408202387, "p": "13748.99000000", "q": "0.00084600", "f": 448745722, "l": 448745722, "T": 1604221203265, "m": false, "M": true}, {"e": "aggTrade", "E": 1604221203316, "s": "BTCUSDT", "a": 408202388, "p": "13748.99000000", "q": "1.22360800", "f": 448745723, "l": 448745723, "T": 1604221203314, "m": false, "M": true}, {"e": "aggTrade", "E": 1604221203670, "s": "BTCUSDT", "a": 408202389, "p": "13748.99000000", "q": "0.05200000", "f": 448745724, "l": 448745724, "T": 1604221203669, "m": false, "M": true}, {"e": "aggTrade", "E": 1604221203688, "s": "BTCUSDT", "a": 408202390, "p": "13748.99000000", "q": "0.40000000", "f": 448745725, "l": 448745725, "T": 1604221203687, "m": false, "M": true}, {"e": "aggTrade", "E": 1604221203912, "s": "BTCUSDT", "a": 408202391, "p": "13748.99000000", "q": "0.03700000", "f": 448745726, "l": 448745726, "T": 1604221203911, "m": false, "M": true}, {"e": "aggTrade", "E": 1604221204425, "s": "BTCUSDT", "a": 408202392, "p": "13748.99000000", "q": "0.02575800", "f": 448745727, "l": 448745731, "T": 1604221204424, "m": false, "M": true}, {"e": "aggTrade", "E": 1604221204425, "s": "BTCUSDT", "a": 408202393, "p": "13749.00000000", "q": "2.24087200", "f": 448745732, "l": 448745732, "T": 1604221204424, "m": false, "M": true}, {"e": "aggTrade", "E": 1604221204745, "s": "BTCUSDT", "a": 408202394, "p": "13749.00000000", "q": "0.29059700", "f": 448745733, "l": 448745733, "T": 1604221204743, "m": false, "M": true}, {"e": "aggTrade", "E": 1604221205560, "s": "BTCUSDT", "a": 408202395, "p": "13749.00000000", "q": "2.31913500", "f": 448745734, "l": 448745734, "T": 1604221205559, "m": false, "M": true}, {"e": "aggTrade", "E": 1604221205737, "s": "BTCUSDT", "a": 408202396, "p": "13749.00000000", "q": "0.00088100", "f": 448745735, "l": 448745735, "T": 1604221205736, "m": false, "M": true}, {"e": "aggTrade", "E": 1604221205811, "s": "BTCUSDT", "a": 408202397, "p": "13749.00000000", "q": "0.29059700", "f": 448745736, "l": 448745736, "T": 1604221205810, "m": false, "M": true}, {"e": "aggTrade", "E": 1604221205929, "s": "BTCUSDT", "a": 408202398, "p": "13749.00000000", "q": "0.03793200", "f": 448745737, "l": 448745737, "T": 1604221205928, "m": false, "M": true}, {"e": "aggTrade", "E": 1604221205932, "s": "BTCUSDT", "a": 408202399, "p": "13749.00000000", "q": "0.11380400", "f": 448745738, "l": 448745738, "T": 1604221205931, "m": false, "M": true}, {"e": "aggTrade", "E": 1604221205970, "s": "BTCUSDT", "a": 408202400, "p": "13749.00000000", "q": "0.03792600", "f": 448745739, "l": 448745739, "T": 1604221205969, "m": false, "M": true}, {"e": "aggTrade", "E": 1604221206273, "s": "BTCUSDT", "a": 408202401, "p": "13748.99000000", "q": "0.00100000", "f": 448745740, "l": 448745740, "T": 1604221206272, "m": true, "M": true}, {"e": "aggTrade", "E": 1604221206655, "s": "BTCUSDT", "a": 408202402, "p": "13749.00000000", "q": "20.00000000", "f": 448745741, "l": 448745741, "T": 1604221206654, "m": false, "M": true}, {"e": "aggTrade", "E": 1604221206767, "s": "BTCUSDT", "a": 408202403, "p": "13749.00000000", "q": "0.29059700", "f": 448745742, "l": 448745742, "T": 1604221206766, "m": false, "M": true}, {"e": "aggTrade", "E": 1604221206805, "s": "BTCUSDT", "a": 408202404, "p": "13749.00000000", "q": "0.30000000", "f": 448745743, "l": 448745743, "T": 1604221206804, "m": false, "M": true}, {"e": "aggTrade", "E": 1604221206931, "s": "BTCUSDT", "a": 408202405, "p": "13749.00000000", "q": "2.32587300", "f": 448745744, "l": 448745744, "T": 1604221206930, "m": false, "M": true}, {"e": "aggTrade", "E": 1604221207655, "s": "BTCUSDT", "a": 408202406, "p": "13749.00000000", "q": "0.00200000", "f": 448745745, "l": 448745745, "T": 1604221207654, "m": false, "M": true}, {"e": "aggTrade", "E": 1604221207803, "s": "BTCUSDT", "a": 408202407, "p": "13749.00000000", "q": "0.29059700", "f": 448745746, "l": 448745746, "T": 1604221207802, "m": false, "M": true}, {"e": "aggTrade", "E": 1604221207937, "s": "BTCUSDT", "a": 408202408, "p": "13749.00000000", "q": "1.92924600", "f": 448745747, "l": 448745747, "T": 1604221207936, "m": false, "M": true}, {"e": "aggTrade", "E": 1604221208079, "s": "BTCUSDT", "a": 408202409, "p": "13749.00000000", "q": "0.063
