sample_data/BTCUSDT/2020-11-01T10-00-00_trades.json
[{"e": "aggTrade", "E": 1604224800094, "s": "BTCUSDT", "a": 408220421, "p": "13687.52000000", "q": "0.00397600", "f": 448768361, "l": 448768362, "T": 1604224800093, "m": true, "M": true}, {"e": "aggTrade", "E": 1604224800202, "s": "BTCUSDT", "a": 408220422, "p": "13687.52000000", "q": "0.00200200", "f": 448768363, "l": 448768364, "T": 1604224800200, "m": true, "M": true}, {"e": "aggTrade", "E": 1604224800232, "s": "BTCUSDT", "a": 408220423, "p": "13687.53000000", "q": "0.06036000", "f": 448768365, "l": 448768365, "T": 1604224800231, "m": false, "M": true}, {"e": "aggTrade", "E": 1604224800635, "s": "BTCUSDT", "a": 408220424, "p": "13687.52000000", "q": "0.00730300", "f": 448768366, "l": 448768367, "T": 1604224800634, "m": true, "M": true}, {"e": "aggTrade", "E": 1604224800689, "s": "BTCUSDT", "a": 408220425, "p": "13687.53000000", "q": "0.06031000", "f": 448768368, "l": 448768368, "T": 1604224800688, "m": false, "M": true}, {"e": "aggTrade", "E": 1604224800797, "s": "BTCUSDT", "a": 408220426, "p": "13687.52000000", "q": "0.00001200", "f": 448768369, "l": 448768369, "T": 1604224800796, "m": true, "M": true}, {"e": "aggTrade", "E": 1604224800843, "s": "BTCUSDT", "a": 408220427, "p": "13687.24000000", "q": "0.00739800", "f": 448768370, "l": 448768370, "T": 1604224800842, "m": false, "M": true}, {"e": "aggTrade", "E": 1604224800920, "s": "BTCUSDT", "a": 408220428, "p": "13687.23000000", "q": "0.02097900", "f": 448768371, "l": 448768373, "T": 1604224800919, "m": true, "M": true}, {"e": "aggTrade", "E": 1604224801124, "s": "BTCUSDT", "a": 408220429, "p": "13686.81000000", "q": "0.06111500", "f": 448768374, "l": 448768375, "T": 1604224801122, "m": false, "M": true}, {"e": "aggTrade", "E": 1604224801126, "s": "BTCUSDT", "a": 408220430, "p": "13686.80000000", "q": "0.00899500", "f": 448768376, "l": 448768376, "T": 1604224801125, "m": true, "M": true}, {"e": "aggTrade", "E": 1604224801259, "s": "BTCUSDT", "a": 408220431, "p": "13686.80000000", "q": "0.00864000", "f": 448768377, "l": 448768378, "T": 1604224801258, "m": true, "M": true}, {"e": "aggTrade", "E": 1604224801314, "s": "BTCUSDT", "a": 408220432, "p": "13686.81000000", "q": "0.00080300", "f": 448768379, "l": 448768379, "T": 1604224801313, "m": false, "M": true}, {"e": "aggTrade", "E": 1604224801325, "s": "BTCUSDT", "a": 408220433, "p": "13686.80000000", "q": "0.51726400", "f": 448768380, "l": 448768381, "T": 1604224801323, "m": true, "M": true}, {"e": "aggTrade", "E": 1604224801441, "s": "BTCUSDT", "a": 408220434, "p": "13686.80000000", "q": "0.60929000", "f": 448768382, "l": 448768382, "T": 1604224801440, "m": true, "M": true}, {"e": "aggTrade", "E": 1604224801442, "s": "BTCUSDT", "a": 408220435, "p": "13686.36000000", "q": "0.01003500", "f": 448768383, "l": 448768384, "T": 1604224801441, "m": true, "M": true}, {"e": "aggTrade", "E": 1604224801442, "s": "BTCUSDT", "a": 408220436, "p": "13686.12000000", "q": "0.01900400", "f": 448768385, "l": 448768385, "T": 1604224801441, "m": true, "M": true}, {"e": "aggTrade", "E": 1604224801442, "s": "BTCUSDT", "a": 408220437, "p": "13684.62000000", "q": "0.00146100", "f": 448768386, "l": 448768386, "T": 1604224801441, "m": true, "M": true}, {"e": "aggTrade", "E": 1604224801442, "s": "BTCUSDT", "a": 408220438, "p": "13684.61000000", "q": "0.11868100", "f": 448768387, "l": 448768387, "T": 1604224801441, "m": true, "M": true}, {"e": "aggTrade", "E": 1604224801442, "s": "BTCUSDT", "a": 408220439, "p": "13683.77000000", "q": "0.01000000", "f": 448768388, "l": 448768388, "T": 1604224801441, "m": true, "M": true}, {"e": "aggTrade", "E": 1604224801442, "s": "BTCUSDT", "a": 408220440, "p": "13683.76000000", "q": "0.14652200", "f": 448768389, "l": 448768389, "T": 1604224801441, "m": true, "M": true}, {"e": "aggTrade", "E": 1604224801442, "s": "BTCUSDT", "a": 408220441, "p": "13683.57000000", "q": "0.01533100", "f": 448768390, "l": 448768390, "T": 1604224801441, "m": true, "M": true}, {"e": "aggTrade", "E": 1604224801521, "s": "BTCUSDT", "a": 408220442, "p": "13686.13000000", "q": "0.00679300", "f": 448768391, "l": 448768391, "T": 1604224801520, "m": false, "M": true}, {"e": "aggTrade", "E": 1604224801531, "s": "BTCUSDT", "a": 408220443, "p": "13686.13000000", "q": "0.06001400", "f": 448768392, "l": 448768392, "T": 1604224801530, "m": false, "M": true}, {"e": "aggTrade", "E": 1604224801788, "s": "BTCUSDT", "a": 408220444, "p": "13686.13000000", "q": "0.00241400", "f": 448768393, "l": 448768393, "T": 1604224801787, "m": false, "M": true}, {"e": "aggTrade", "E": 1604224801927, "s": "BTCUSDT", "a": 408220445, "p": "13686.13000000", "q": "0.00079800", "f": 448768394, "l": 448768394, "T": 1604224801926, "m": false, "M": true}, {"e": "aggTrade", "E": 1604224801940, "s": "BTCUSDT", "a": 408220446, "p": "13686.13000000", "q": "0.06043100", "f": 448768395, "l": 448768395, "T": 1604224801939, "m": false, "M": true}, {"e": "aggTrade", "E": 1604224802347, "s": "BTCUSDT", "a": 408220447, "p": "13686.13000000", "q": "0.06000900", "f": 448768396, "l": 448768396, "T": 1604224802346, "m": false, "M": true}, {"e": "aggTrade", "E": 1604224802643, "s": "BTCUSDT", "a": 408220448, "p": "13686.13000000", "q": "0.00088100", "f": 448768397, "l": 448768397, "T": 1604224802642, "m": false, "M": true}, {"e": "aggTrade", "E": 1604224802758, "s": "BTCUSDT", "a": 408220449, "p": "13686.13000000", "q": "0.06023700", "f": 448768398, "l": 448768398, "T": 1604224802757, "m": false, "M": true}, {"e": "aggTrade", "E": 1604224802808, "s": "BTCUSDT", "a": 408220450, "p": "13686.12000000", "q": "0.01280300", "f": 448768399, "l": 448768401, "T": 1604224802807, "m": true, "M": true}, {"e": "aggTrade", "E": 1604224802945, "s": "BTCUSDT", "a": 408220451, "p": "13686.12000000", "q": "0.00205000", "f": 448768402, "l": 448768402, "T": 1604224802944, "m": true, "M": true}, {"e": "aggTrade", "E": 1604224803044, "s": "BTCUSDT", "a": 408220452, "p": "13686.12000000", "q": "0.01276000", "f": 448768403, "l": 448768404, "T": 1604224803043, "m": true, "M": true}, {"e": "aggTrade", "E": 1604224803206, "s": "BTCUSDT", "a": 408220453, "p": "13685.21000000", "q": "0.06008300", "f": 448768405, "l": 448768406, "T": 1604224803204, "m": false, "M": true}, {"e": "aggTrade", "E": 1604224803573, "s": "BTCUSDT", "a": 408220454, "p": "13685.20000000", "q": "0.00900000", "f": 448768407, "l": 448768407, "T": 1604224803572, "m": true, "M": true}, {"e": "aggTrade", "E": 1604224803573, "s": "BTCUSDT", "a": 408220455, "p": "13684.27000000", "q": "0.00146100", "f": 448768408, "l": 448768408, "T": 1604224803572, "m": true, "M": true}, {"e": "aggTrade", "E": 1604224803573, "s": "BTCUSDT", "a": 408220456, "p": "13683.50000000", "q": "0.03750000", "f": 448768409, "l": 448768409, "T": 1604224803572, "m": true, "M": true}, {"e": "aggTrade", "E": 1604224803573, "s": "BTCUSDT", "a": 408220457, "p": "13683.01000000", "q": "0.04533000", "f": 448768410, "l": 448768410, "T": 1604224803572, "m": true, "M": true}, {"e": "aggTrade", "E": 1604224803573, "s": "BTCUSDT", "a": 408220458, "p": "13683.00000000", "q": "0.03750000", "f": 448768411, "l": 448768411, "T": 1604224803572, "m": true, "M": true}, {"e": "aggTrade", "E": 1604224803573, "s": "BTCUSDT", "a": 408220459, "p": "13682.94000000", "q": "0.27080000", "f": 448768412, "l": 448768412, "T": 1604224803572, "m": true, "M": true}, {"e": "aggTrade", "E": 1604224803624, "s": "BTCUSDT", "a": 408220460, "p": "13684.08000000", "q": "0.06041300", "f": 448768413, "l": 448768414, "T": 1604224803623, "m": false, "M": true}, {"e": "aggTrade", "E": 1604224803648, "s": "BTCUSDT", "a": 408220461, "p": "13684.08000000", "q": "0.00364000", "f": 448768415, "l": 448768415, "T": 1604224803647, "m": false, "M": true}, {"e": "aggTrade", "E": 1604224803760, "s": "BTCUSDT", "a": 408220462, "p": "13684.08000000", "q": "0.00400000", "f": 448768416, "l": 448768416, "T": 1604224803759, "m": false, "M": true}, {"e": "aggTrade", "E": 1604224803783, "s": "BTCUSDT", "a": 408220463, "p": "13684.07000000", "q": "0.50756500", "f": 448768417, 
